Workbook

Sheet Data Quality Check
A1: Missing Values Check. | E1: Group Count Check | H1: Duplicate User ID Check | L1: Invalid Binary Value Check | T1: Revenue Outlier Check
A2: Column | B2: Missing Values | E2: Experiment Group | F2: Count | H2: Check | I2: Result | L2: Column | M2: Invalid Values
A3: user_id | B3: =COUNTBLANK('experiment data'!A2:A1409) -> 10 | E3: Control | F3: =COUNTIF('experiment data'!C:C,"Control") -> 681 | H3: Duplicate User IDs | I3: =COUNTA('experiment data'!A:A)-COUNTA(_xlfn.UNIQUE('experiment data'!A:A)) -> -1 | L3: visited_landing_page | M3: 0
A4: experiment_group | B4: =COUNTBLANK('experiment data'!C2:C1409) -> 10 | E4: Treatment | F4: =COUNTIF('experiment data'!C:C,"Treatment") -> 710 | L4: started_trial | M4: 0
A5: region | B5: =COUNTBLANK('experiment data'!D2:D1409) -> 8 | L5: completed_onboarding | M5: 0
A6: device_type | B6: =COUNTBLANK('experiment data'!E2:E1409) -> 28 | L6: converted_to_paid | M6: 0
A7: traffic_source | B7: 24 | L7: refund_requested | M7: 0
A8: plan_type | B8: 0
A9: visited_landing_page | B9: 0
A10: started_trial | B10: 0
A11: completed_onboarding | B11: 0
A12: converted_to_paid | B12: 0
A13: revenue_30d | B13: 0
A14: support_tickets_30d | B14: 0
A15: refund_requested | B15: 0
A16: days_to_convert | B16: 1336
A17: engagement_score | B17: 14

Sheet experiment data
A1: user_id | B1: signup_date | C1: experiment_group | D1: Better Group | E1: Risk | F1: traffic_source | G1: plan_type | H1: visited_landing_page | I1: started_trial | J1: completed_onboarding | K1: converted_to_paid | L1: revenue_30d | M1: support_tickets_30d | N1: refund_requested | O1: days_to_convert | P1: engagement_score
A2: USR-100001 | B2: =COUNTIF('experiment data'!$C:$C,"Control") -> 681 | C2: =COUNTIF('experiment data'!$C:$C,"Treatment") -> 710 | D2: =IF(B2<C2,"Control","Treatment") -> Control | E2: Lower refund rate is preerred. | F2: Email | G2: Basic | H2: 0 | L2: 0 | M2: 0 | N2: 0 | P2: 45.7
A3: USR-100002 | B3: =COUNTIFS('experiment data'!$C:$C,"Control",'experiment data'!$M:$M,">0")/COUNTIF('experiment data'!$C:$C,"Control") -> 0.14831131 | C3: =COUNTIFS('experiment data'!$C:$C,"Treatment",'experiment data'!$M:$M,">0")/COUNTIF('experiment data'!$C:$C,"Treatment") -> 0.24788732 | D3: =IF(B3<C3,"Control","Treatment") -> Control | E3: Lower support ticket rate is preferred. | F3: Organic | G3: Free | H3: 1 | L3: 0 | M3: 0 | N3: 0 | P3: 48.6
A4: Average Days to Convert | B4: =AVERAGEIFS('experiment data'!$O:$O,'experiment data'!$C:$C,"Control") -> 8.8636364 | C4: =AVERAGEIFS('experiment data'!$O:$O,'experiment data'!$C:$C,"Treatment") -> 6.4 | D4: =IF(B4<C4,"Control","Treatment") -> Treatment | E4: Lower conversion time is preferred. | F4: Paid Search | G4: Premium | H4: 1 | I4: 0 | J4: 0 | K4: 0 | L4: 0 | M4: 1 | N4: 0 | P4: 35.4
A5: Average Engagement Score | B5: =AVERAGEIFS('experiment data'!$P:$P,'experiment data'!$C:$C,"Control") -> 57.10237 | C5: =AVERAGEIFS('experiment data'!$P:$P,'experiment data'!$C:$C,"Treatment") -> 62.940028 | D5: =IF(B5>C5,"Control","Treatment") -> Treatment | E5: Higher engagement is preferred. | F5: Email | G5: Basic | H5: 1 | I5: 0 | J5: 0 | K5: 0 | L5: 0 | M5: 0 | N5: 0 | P5: 64.6
A6: USR-100005 | B6: 45700 | C6: Control | D6: North | E6: Tablet | F6: Organic | G6: Free | H6: 0 | I6: 0 | J6: 0 | K6: 0 | L6: 0 | M6: 0 | N6: 0 | P6: 66.6
A7: USR-100006 | B7: 45685 | C7: Control | D7: East | E7: Mobile | F7: Organic | G7: Premium | H7: 1 | I7: 0 | J7: 0 | K7: 0 | L7: 0 | M7: 0 | N7: 0 | P7: 40.8
B8: 45755 | D8: East | F8: Paid Search | H8: 1 | I8: 1 | J8: 0 | K8: 0 | L8: 0 | M8: 0 | N8: 0 | P8: 57.1
D9: South | H9: 0 | I9: 0 | J9: 0 | K9: 0 | L9: 0 | M9: 0 | N9: 0 | P9: 36.4
A10: South | B10: 0 | C10: 0 | D10: 0 | E10: 0 | F10: 0 | G10: 0 | H10: 0 | J10: 55.4
A11: West | B11: 1 | C11: 0 | D11: 0 | E11: 0 | F11: 0 | G11: 0 | H11: 0 | J11: 57.3
A12: East | B12: 1 | C12: 1 | D12: 1 | E12: 0 | F12: 0 | G12: 0 | H12: 0 | J12: 63.6
A13: USR-100012 | B13: 45732 | C13: Control | D13: East | E13: Mobile | F13: Social | G13: Premium | H13: 1 | I13: 1 | J13: 1 | K13: 0 | L13: 0 | M13: 1 | N13: 0 | P13: 80.4
A14: USR-100013 | B14: 45695 | C14: Control | D14: South | E14: Desktop | F14: Email | G14: Basic | H14: 1 | I14: 0 | J14: 0 | K14: 0 | L14: 0 | M14: 0 | N14: 0 | P14: 62.4
A15: USR-100014 | B15: 45718 | C15: Control | D15: West | E15: Mobile | F15: Social | G15: Basic | H15: 1 | I15: 0 | J15: 0 | K15: 0 | L15: 0 | M15: 0 | N15: 0 | P15: 82.4
A16: USR-100015 | B16: 45807 | C16: Control | D16: South | E16: Mobile | F16: Organic | G16: Basic | H16: 0 | I16: 0 | J16: 0 | K16: 0 | L16: 0 | M16: 0 | N16: 0 | P16: 61.2
A17: USR-100016 | B17: 45741 | C17: Control | D17: South | E17: Mobile | F17: Social | G17: Basic | H17: 1 | I17: 0 | J17: 0 | K17: 0 | L17: 0 | M17: 0 | N17: 0 | P17: 68.9
A18: USR-100017 | B18: 45743 | C18: Control | D18: East | E18: Desktop | F18: Paid Search | G18: Free | H18: 1 | I18: 1 | J18: 1 | K18: 0 | L18: 0 | M18: 0 | N18: 0 | P18: 71.9
A19: USR-100018 | B19: 45805 | C19: Control | D19: South | E19: Desktop | F19: Paid Search | G19: Free | H19: 0 | I19: 0 | J19: 0 | K19: 0 | L19: 0 | M19: 0 | N19: 0 | P19: 50.5
A20: USR-100019 | B20: 45703 | C20: Control | D20: North | E20: Desktop | F20: Paid Search | G20: Basic | H20: 0 | I20: 0 | J20: 0 | K20: 0 | L20: 0 | M20: 0 | N20: 0 | P20: 49.3
A21: USR-100020 | B21: 45782 | C21: Control | D21: West | E21: Desktop | F21: Organic | G21: Basic | H21: 0 | I21: 0 | J21: 0 | K21: 0 | L21: 0 | M21: 2 | N21: 0 | P21: 60.9
A22: USR-100021 | B22: 45760 | C22: Control | D22: East | E22: Mobile | F22: Social | G22: Free | H22: 1 | I22: 0 | J22: 0 | K22: 0 | L22: 0 | M22: 0 | N22: 0 | P22: 62.7
A23: USR-100022 | B23: 45784 | C23: Control | D23: North | E23: Desktop | F23: Paid Search | G23: Free | H23: 0 | I23: 0 | J23: 0 | K23: 0 | L23: 0 | M23: 0 | N23: 0 | P23: 52.7
A24: USR-100023 | B24: 45802 | C24: Control | D24: North | E24: Desktop | F24: Organic | G24: Free | H24: 0 | I24: 0 | J24: 0 | K24: 0 | L24: 0 | M24: 0 | N24: 0 | P24: 54
... A60: USR-100059 | B60: 45761 | C60: Control | D60: North | E60: Mobile | F60: Social | G60: Free | H60: 0 | I60: 0 | J60: 0 | K60: 0 | L60: 0 | M60: 2 | N60: 0 | P60: 48.9
A61: USR-100060 | B61: 45658 | C61: Control | D61: West | E61: Mobile | F61: Social | G61: Free | H61: 1 | I61: 1 | J61: 1 | K61: 1 | L61: 240.42 | M61: 0 | N61: 0 | O61: 16 | P61: 56.5
A62: USR-100061 | B62: 45749 | C62: Control | D62: South | E62: Mobile | F62: Referral | G62: Free | H62: 1 | I62: 0 | J62: 0 | K62: 0 | L62: 0 | M62: 0 | N62: 0 | P62: 53.7
A63: USR-100062 | B63: 45745 | C63: Control | D63: North | E63: Mobile | F63: Social | G63: Premium | H63: 0 | I63: 0 | J63: 0 | K63: 0 | L63: 0 | M63: 0 | N63: 0 | P63: 62.2
A64: USR-100063 | B64: 45792 | C64: Control | D64: South | E64: Desktop | F64: Organic | G64: Free | H64: 1 | I64: 0 | J64: 0 | K64: 0 | L64: 0 | M64: 0 | N64: 0 | P64: 50.2
A65: USR-100064 | B65: 45758 | C65: Control | D65: North | E65: Mobile | F65: Organic | G65: Basic | H65: 1 | I65: 0 | J65: 0 | K65: 0 | L65: 0 | M65: 0 | N65: 0 | P65: 74.3
A66: USR-100065 | B66: 45723 | C66: Control | D66: South | E66: Desktop | F66: Paid Search | G66: Free | H66: 1 | I66: 0 | J66: 0 | K66: 0 | L66: 0 | M66: 0 | N66: 0 | P66: 58
A67: USR-100066 | B67: 45807 | C67: Control | D67: South | E67: Mobile | F67: Organic | G67: Free | H67: 0 | I67: 0 | J67: 0 | K67: 0 | L67: 0 | M67: 0 | N67: 0 | P67: 46.7
A68: USR-100067 | B68: 45664 | C68: Control | D68: South | E68: Desktop | F68: Organic | G68: Premium | H68: 1 | I68: 0 | J68: 0 | K68: 0 | L68: 0 | M68: 1 | N68: 0 | P68: 49.6
A69: USR-100068 | B69: 45785 | C69: Control | D69: West | E69: Mobile | F69: Social | G69: Free | H69: 0 | I69: 0 | J69: 0 | K69: 0 | L69: 0 | M69: 0 | N69: 0 | P69: 60.4
A70: USR-100069 | B70: 45735 | C70: Control | D70: East | E70: Desktop | F70: Email | G70: Free | H70: 1 | I70: 1 | J70: 1 | K70: 0 | L70: 0 | M70: 0 | N70: 0 | P70: 55.3
A71: USR-100070 | B71: 45793 | C71: Control | D71: North | E71: Desktop | F71: Organic | G71: Free | H71: 0 | I71: 0 | J71: 0 | K71: 0 | L71: 0 | M71: 0 | N71: 0 | P71: 56.2
A72: USR-100071 | B72: 45724 | C72: Control | D72: West | E72: Mobile | F72: Email | G72: Free | H72: 0 | I72: 0 | J72: 0 | K72: 0 | L72: 0 | M72: 0 | N72: 0 | P72: 29.4
A73: USR-100072 | B73: 45724 | C73: Control | D73: East | E73: Mobile | F73: Email | G73: Free | H73: 1 | I73: 0 | J73: 0 | K73: 0 | L73: 0 | M73: 0 | N73: 0 | P73: 54.2
... A79: USR-100078 | B79: 45673 | C79: Control | D79: North | E79: Mobile | F79: Organic | G79: Free | H79: 0 | I79: 0 | J79: 0 | K79: 0 | L79: 0 | M79: 2 | N79: 0 | P79: 48.4
A80: USR-100079 | B80: 45708 | C80: Control | D80: West | E80: Desktop | F80: Organic | G80: Free | H80: 1 | I80: 1 | J80: 1 | K80: 1 | L80: 457.51 | M80: 0 | N80: 0 | O80: 7 | P80: 38
...

Sheet Experiment Summary
A1: Metric | B1: Control | C1: Treatment | D1: Better Group | E1: Risk
A2: Users | B2: 690 | C2: =COUNTIF('experiment data'!$C:$C,"Treatment") -> 710 | D2: =IF(B2<C2,"Control","Treatment") -> Control | E2: Lower refund rate is preerred.
A3: Landing Page Visit Rate | B3: =COUNTIFS('experiment data'!$C:$C,"Control",'experiment data'!$M:$M,">0")/COUNTIF('experiment data'!$C:$C,"Control") -> 0.14831131 | C3: =COUNTIFS('experiment data'!$C:$C,"Treatment",'experiment data'!$M:$M,">0")/COUNTIF('experiment data'!$C:$C,"Treatment") -> 0.24788732 | D3: =IF(B3<C3,"Control","Treatment") -> Control | E3: Lower support ticket rate is preferred.
A4: Average Days to Convert | B4: =AVERAGEIFS('experiment data'!$O:$O,'experiment data'!$C:$C,"Control") -> 8.8636364 | C4: =AVERAGEIFS('experiment data'!$O:$O,'experiment data'!$C:$C,"Treatment") -> 6.4 | D4: =IF(B4<C4,"Control","Treatment") -> Treatment | E4: Lower conversion time is preferred.
A5: Average Engagement Score | B5: =AVERAGEIFS('experiment data'!$P:$P,'experiment data'!$C:$C,"Control") -> 57.10237 | C5: =AVERAGEIFS('experiment data'!$P:$P,'experiment data'!$C:$C,"Treatment") -> 62.940028 | D5: =IF(B5>C5,"Control","Treatment") -> Treatment | E5: Higher engagement is preferred.
A6: Paid Conversion Rate | B6: =AVERAGEIFS('experiment data'!K:K,'experiment data'!C:C,"Control") -> 0.032305433 | C6: =AVERAGEIFS('experiment data'!K:K,'experiment data'!C:C,"Treatment") -> 0.070422535 | D6: =IF(B6>C6,"Control","Treatment") -> Treatment | E6: Higher conversion rate is preferred
A7: Revenue per User | B7: =AVERAGEIFS('experiment data'!L:L,'experiment data'!C:C,"Control") -> 52.661204 | C7: =AVERAGEIFS('experiment data'!L:L,'experiment data'!C:C,"Treatment") -> 54.254521 | D7: =IF(B7>C7,"Control","Treatment") -> Treatment | E7: Higher revenue per user is preffered

Sheet Hypothesis Test
A1: Metric | B1: Control | C1: Treatment | D1: Better Group | E1: Risk | F1: Test Input | G1: Value
A2: Users | B2: =COUNTIF('experiment data'!$C:$C,"Control") -> 681 | C2: =COUNTIF('experiment data'!$C:$C,"Treatment") -> 710 | D2: =IF(B2<C2,"Control","Treatment") -> Control | E2: Lower refund rate is preerred. | F2: Control Users | G2: 690
A3: Converted Users | B3: =COUNTIFS('experiment data'!$C:$C,"Control",'experiment data'!$M:$M,">0")/COUNTIF('experiment data'!$C:$C,"Control") -> 0.14831131 | C3: =COUNTIFS('experiment data'!$C:$C,"Treatment",'experiment data'!$M:$M,">0")/COUNTIF('experiment data'!$C:$C,"Treatment") -> 0.24788732 | D3: =IF(B3<C3,"Control","Treatment") -> Control | E3: Lower support ticket rate is preferred. | F3: Treatment Users | G3: 710
A4: Average Days to Convert | B4: =AVERAGEIFS('experiment data'!$O:$O,'experiment data'!$C:$C,"Control") -> 8.8636364 | C4: =AVERAGEIFS('experiment data'!$O:$O,'experiment data'!$C:$C,"Treatment") -> 6.4 | D4: =IF(B4<C4,"Control","Treatment") -> Treatment | E4: Lower conversion time is preferred. | F4: Control Converted Users | G4: 22
A5: Average Engagement Score | B5: =AVERAGEIFS('experiment data'!$P:$P,'experiment data'!$C:$C,"Control") -> 57.10237 | C5: =AVERAGEIFS('experiment data'!$P:$P,'experiment data'!$C:$C,"Treatment") -> 62.940028 | D5: =IF(B5>C5,"Control","Treatment") -> Treatment | E5: Higher engagement is preferred. | F5: Treatment Converted Users | G5: 50
F6: Control Conversion Rate | G6: 0.0319
F7: Treatment Conversion Rate | G7: 0.0704
F8: Test Used
A13: Decision | B13: Reject H₀
F15: The treatment group achieved a paid conversion rate of 7.04%, compared to 3.19% for the control group.
F16: Since the p-value (0.00055) is less than the significance level (0.05), the null hypothesis is rejected.
F17: This indicates that the treatment significantly improved the paid conversion rate.

Sheet Guardrail Metrics
A1: Metric | B1: Control | C1: Treatment | D1: Better Group | E1: Risk
A2: Refund Rate | B2: =COUNTIF('experiment data'!$C:$C,"Control") -> 681 | C2: =COUNTIF('experiment data'!$C:$C,"Treatment") -> 710 | D2: =IF(B2<C2,"Control","Treatment") -> Control | E2: Lower refund rate is preerred.
A3: Support Ticket Rate | B3: =COUNTIFS('experiment data'!$C:$C,"Control",'experiment data'!$M:$M,">0")/COUNTIF('experiment data'!$C:$C,"Control") -> 0.14831131 | C3: =COUNTIFS('experiment data'!$C:$C,"Treatment",'experiment data'!$M:$M,">0")/COUNTIF('experiment data'!$C:$C,"Treatment") -> 0.24788732 | D3: =IF(B3<C3,"Control","Treatment") -> Control | E3: Lower support ticket rate is preferred.
A4: Average Days to Convert | B4: =AVERAGEIFS('experiment data'!$O:$O,'experiment data'!$C:$C,"Control") -> 8.8636364 | C4: =AVERAGEIFS('experiment data'!$O:$O,'experiment data'!$C:$C,"Treatment") -> 6.4 | D4: =IF(B4<C4,"Control","Treatment") -> Treatment | E4: Lower conversion time is preferred.
A5: Average Engagement Score | B5: =AVERAGEIFS('experiment data'!$P:$P,'experiment data'!$C:$C,"Control") -> 57.10237 | C5: =AVERAGEIFS('experiment data'!$P:$P,'experiment data'!$C:$C,"Treatment") -> 62.940028 | D5: =IF(B5>C5,"Control","Treatment") -> Treatment | E5: Higher engagement is preferred.
